{
 "cells": [
  {
   "cell_type": "markdown",
   "metadata": {},
   "source": [
    "INSTALL LIBRARY\n",
    "pip install redis"
   ]
  },
  {
   "cell_type": "code",
   "execution_count": 1,
   "metadata": {},
   "outputs": [
    {
     "name": "stdout",
     "output_type": "stream",
     "text": [
      "Requirement already satisfied: redis in /usr/local/lib/python3.10/dist-packages (5.0.6)\n",
      "Requirement already satisfied: async-timeout>=4.0.3 in /usr/local/lib/python3.10/dist-packages (from redis) (4.0.3)\n",
      "\u001b[33mWARNING: Running pip as the 'root' user can result in broken permissions and conflicting behaviour with the system package manager. It is recommended to use a virtual environment instead: https://pip.pypa.io/warnings/venv\u001b[0m\u001b[33m\n",
      "\u001b[0mNote: you may need to restart the kernel to use updated packages.\n"
     ]
    }
   ],
   "source": [
    "pip install redis"
   ]
  },
  {
   "cell_type": "markdown",
   "metadata": {},
   "source": [
    "IMPORT LIBRARY"
   ]
  },
  {
   "cell_type": "code",
   "execution_count": 2,
   "metadata": {},
   "outputs": [],
   "source": [
    "import redis"
   ]
  },
  {
   "cell_type": "markdown",
   "metadata": {},
   "source": [
    "CREATE CONNECTION"
   ]
  },
  {
   "cell_type": "code",
   "execution_count": 4,
   "metadata": {},
   "outputs": [],
   "source": [
    "# Redis connection parameters\n",
    "redis_host = 'localhost'\n",
    "redis_port = 6379\n",
    "redis_password = None  # If your Redis server doesn't require a password, set this to None\n",
    "\n",
    "# Connect to Redis server\n",
    "redis_client = redis.Redis(host=redis_host, port=redis_port, password=redis_password)"
   ]
  },
  {
   "cell_type": "markdown",
   "metadata": {},
   "source": [
    "INSERT DATA"
   ]
  },
  {
   "cell_type": "code",
   "execution_count": 5,
   "metadata": {},
   "outputs": [
    {
     "ename": "ConnectionError",
     "evalue": "Error 111 connecting to localhost:6379. Connection refused.",
     "output_type": "error",
     "traceback": [
      "\u001b[0;31m---------------------------------------------------------------------------\u001b[0m",
      "\u001b[0;31mConnectionRefusedError\u001b[0m                    Traceback (most recent call last)",
      "File \u001b[0;32m/usr/local/lib/python3.10/dist-packages/redis/connection.py:276\u001b[0m, in \u001b[0;36mAbstractConnection.connect\u001b[0;34m(self)\u001b[0m\n\u001b[1;32m    275\u001b[0m \u001b[38;5;28;01mtry\u001b[39;00m:\n\u001b[0;32m--> 276\u001b[0m     sock \u001b[38;5;241m=\u001b[39m \u001b[38;5;28;43mself\u001b[39;49m\u001b[38;5;241;43m.\u001b[39;49m\u001b[43mretry\u001b[49m\u001b[38;5;241;43m.\u001b[39;49m\u001b[43mcall_with_retry\u001b[49m\u001b[43m(\u001b[49m\n\u001b[1;32m    277\u001b[0m \u001b[43m        \u001b[49m\u001b[38;5;28;43;01mlambda\u001b[39;49;00m\u001b[43m:\u001b[49m\u001b[43m \u001b[49m\u001b[38;5;28;43mself\u001b[39;49m\u001b[38;5;241;43m.\u001b[39;49m\u001b[43m_connect\u001b[49m\u001b[43m(\u001b[49m\u001b[43m)\u001b[49m\u001b[43m,\u001b[49m\u001b[43m \u001b[49m\u001b[38;5;28;43;01mlambda\u001b[39;49;00m\u001b[43m \u001b[49m\u001b[43merror\u001b[49m\u001b[43m:\u001b[49m\u001b[43m \u001b[49m\u001b[38;5;28;43mself\u001b[39;49m\u001b[38;5;241;43m.\u001b[39;49m\u001b[43mdisconnect\u001b[49m\u001b[43m(\u001b[49m\u001b[43merror\u001b[49m\u001b[43m)\u001b[49m\n\u001b[1;32m    278\u001b[0m \u001b[43m    \u001b[49m\u001b[43m)\u001b[49m\n\u001b[1;32m    279\u001b[0m \u001b[38;5;28;01mexcept\u001b[39;00m socket\u001b[38;5;241m.\u001b[39mtimeout:\n",
      "File \u001b[0;32m/usr/local/lib/python3.10/dist-packages/redis/retry.py:46\u001b[0m, in \u001b[0;36mRetry.call_with_retry\u001b[0;34m(self, do, fail)\u001b[0m\n\u001b[1;32m     45\u001b[0m \u001b[38;5;28;01mtry\u001b[39;00m:\n\u001b[0;32m---> 46\u001b[0m     \u001b[38;5;28;01mreturn\u001b[39;00m \u001b[43mdo\u001b[49m\u001b[43m(\u001b[49m\u001b[43m)\u001b[49m\n\u001b[1;32m     47\u001b[0m \u001b[38;5;28;01mexcept\u001b[39;00m \u001b[38;5;28mself\u001b[39m\u001b[38;5;241m.\u001b[39m_supported_errors \u001b[38;5;28;01mas\u001b[39;00m error:\n",
      "File \u001b[0;32m/usr/local/lib/python3.10/dist-packages/redis/connection.py:277\u001b[0m, in \u001b[0;36mAbstractConnection.connect.<locals>.<lambda>\u001b[0;34m()\u001b[0m\n\u001b[1;32m    275\u001b[0m \u001b[38;5;28;01mtry\u001b[39;00m:\n\u001b[1;32m    276\u001b[0m     sock \u001b[38;5;241m=\u001b[39m \u001b[38;5;28mself\u001b[39m\u001b[38;5;241m.\u001b[39mretry\u001b[38;5;241m.\u001b[39mcall_with_retry(\n\u001b[0;32m--> 277\u001b[0m         \u001b[38;5;28;01mlambda\u001b[39;00m: \u001b[38;5;28;43mself\u001b[39;49m\u001b[38;5;241;43m.\u001b[39;49m\u001b[43m_connect\u001b[49m\u001b[43m(\u001b[49m\u001b[43m)\u001b[49m, \u001b[38;5;28;01mlambda\u001b[39;00m error: \u001b[38;5;28mself\u001b[39m\u001b[38;5;241m.\u001b[39mdisconnect(error)\n\u001b[1;32m    278\u001b[0m     )\n\u001b[1;32m    279\u001b[0m \u001b[38;5;28;01mexcept\u001b[39;00m socket\u001b[38;5;241m.\u001b[39mtimeout:\n",
      "File \u001b[0;32m/usr/local/lib/python3.10/dist-packages/redis/connection.py:639\u001b[0m, in \u001b[0;36mConnection._connect\u001b[0;34m(self)\u001b[0m\n\u001b[1;32m    638\u001b[0m \u001b[38;5;28;01mif\u001b[39;00m err \u001b[38;5;129;01mis\u001b[39;00m \u001b[38;5;129;01mnot\u001b[39;00m \u001b[38;5;28;01mNone\u001b[39;00m:\n\u001b[0;32m--> 639\u001b[0m     \u001b[38;5;28;01mraise\u001b[39;00m err\n\u001b[1;32m    640\u001b[0m \u001b[38;5;28;01mraise\u001b[39;00m \u001b[38;5;167;01mOSError\u001b[39;00m(\u001b[38;5;124m\"\u001b[39m\u001b[38;5;124msocket.getaddrinfo returned an empty list\u001b[39m\u001b[38;5;124m\"\u001b[39m)\n",
      "File \u001b[0;32m/usr/local/lib/python3.10/dist-packages/redis/connection.py:627\u001b[0m, in \u001b[0;36mConnection._connect\u001b[0;34m(self)\u001b[0m\n\u001b[1;32m    626\u001b[0m \u001b[38;5;66;03m# connect\u001b[39;00m\n\u001b[0;32m--> 627\u001b[0m \u001b[43msock\u001b[49m\u001b[38;5;241;43m.\u001b[39;49m\u001b[43mconnect\u001b[49m\u001b[43m(\u001b[49m\u001b[43msocket_address\u001b[49m\u001b[43m)\u001b[49m\n\u001b[1;32m    629\u001b[0m \u001b[38;5;66;03m# set the socket_timeout now that we're connected\u001b[39;00m\n",
      "\u001b[0;31mConnectionRefusedError\u001b[0m: [Errno 111] Connection refused",
      "\nDuring handling of the above exception, another exception occurred:\n",
      "\u001b[0;31mConnectionError\u001b[0m                           Traceback (most recent call last)",
      "Cell \u001b[0;32mIn[5], line 2\u001b[0m\n\u001b[1;32m      1\u001b[0m \u001b[38;5;66;03m# Insert sample data\u001b[39;00m\n\u001b[0;32m----> 2\u001b[0m \u001b[43mredis_client\u001b[49m\u001b[38;5;241;43m.\u001b[39;49m\u001b[43mset\u001b[49m\u001b[43m(\u001b[49m\u001b[38;5;124;43m'\u001b[39;49m\u001b[38;5;124;43mname\u001b[39;49m\u001b[38;5;124;43m'\u001b[39;49m\u001b[43m,\u001b[49m\u001b[43m \u001b[49m\u001b[38;5;124;43m'\u001b[39;49m\u001b[38;5;124;43mAni\u001b[39;49m\u001b[38;5;124;43m'\u001b[39;49m\u001b[43m)\u001b[49m\n\u001b[1;32m      3\u001b[0m redis_client\u001b[38;5;241m.\u001b[39mset(\u001b[38;5;124m'\u001b[39m\u001b[38;5;124mage\u001b[39m\u001b[38;5;124m'\u001b[39m, \u001b[38;5;241m20\u001b[39m)\n",
      "File \u001b[0;32m/usr/local/lib/python3.10/dist-packages/redis/commands/core.py:2342\u001b[0m, in \u001b[0;36mBasicKeyCommands.set\u001b[0;34m(self, name, value, ex, px, nx, xx, keepttl, get, exat, pxat)\u001b[0m\n\u001b[1;32m   2339\u001b[0m     pieces\u001b[38;5;241m.\u001b[39mappend(\u001b[38;5;124m\"\u001b[39m\u001b[38;5;124mGET\u001b[39m\u001b[38;5;124m\"\u001b[39m)\n\u001b[1;32m   2340\u001b[0m     options[\u001b[38;5;124m\"\u001b[39m\u001b[38;5;124mget\u001b[39m\u001b[38;5;124m\"\u001b[39m] \u001b[38;5;241m=\u001b[39m \u001b[38;5;28;01mTrue\u001b[39;00m\n\u001b[0;32m-> 2342\u001b[0m \u001b[38;5;28;01mreturn\u001b[39;00m \u001b[38;5;28;43mself\u001b[39;49m\u001b[38;5;241;43m.\u001b[39;49m\u001b[43mexecute_command\u001b[49m\u001b[43m(\u001b[49m\u001b[38;5;124;43m\"\u001b[39;49m\u001b[38;5;124;43mSET\u001b[39;49m\u001b[38;5;124;43m\"\u001b[39;49m\u001b[43m,\u001b[49m\u001b[43m \u001b[49m\u001b[38;5;241;43m*\u001b[39;49m\u001b[43mpieces\u001b[49m\u001b[43m,\u001b[49m\u001b[43m \u001b[49m\u001b[38;5;241;43m*\u001b[39;49m\u001b[38;5;241;43m*\u001b[39;49m\u001b[43moptions\u001b[49m\u001b[43m)\u001b[49m\n",
      "File \u001b[0;32m/usr/local/lib/python3.10/dist-packages/redis/client.py:542\u001b[0m, in \u001b[0;36mRedis.execute_command\u001b[0;34m(self, *args, **options)\u001b[0m\n\u001b[1;32m    540\u001b[0m pool \u001b[38;5;241m=\u001b[39m \u001b[38;5;28mself\u001b[39m\u001b[38;5;241m.\u001b[39mconnection_pool\n\u001b[1;32m    541\u001b[0m command_name \u001b[38;5;241m=\u001b[39m args[\u001b[38;5;241m0\u001b[39m]\n\u001b[0;32m--> 542\u001b[0m conn \u001b[38;5;241m=\u001b[39m \u001b[38;5;28mself\u001b[39m\u001b[38;5;241m.\u001b[39mconnection \u001b[38;5;129;01mor\u001b[39;00m \u001b[43mpool\u001b[49m\u001b[38;5;241;43m.\u001b[39;49m\u001b[43mget_connection\u001b[49m\u001b[43m(\u001b[49m\u001b[43mcommand_name\u001b[49m\u001b[43m,\u001b[49m\u001b[43m \u001b[49m\u001b[38;5;241;43m*\u001b[39;49m\u001b[38;5;241;43m*\u001b[39;49m\u001b[43moptions\u001b[49m\u001b[43m)\u001b[49m\n\u001b[1;32m    544\u001b[0m \u001b[38;5;28;01mtry\u001b[39;00m:\n\u001b[1;32m    545\u001b[0m     \u001b[38;5;28;01mreturn\u001b[39;00m conn\u001b[38;5;241m.\u001b[39mretry\u001b[38;5;241m.\u001b[39mcall_with_retry(\n\u001b[1;32m    546\u001b[0m         \u001b[38;5;28;01mlambda\u001b[39;00m: \u001b[38;5;28mself\u001b[39m\u001b[38;5;241m.\u001b[39m_send_command_parse_response(\n\u001b[1;32m    547\u001b[0m             conn, command_name, \u001b[38;5;241m*\u001b[39margs, \u001b[38;5;241m*\u001b[39m\u001b[38;5;241m*\u001b[39moptions\n\u001b[1;32m    548\u001b[0m         ),\n\u001b[1;32m    549\u001b[0m         \u001b[38;5;28;01mlambda\u001b[39;00m error: \u001b[38;5;28mself\u001b[39m\u001b[38;5;241m.\u001b[39m_disconnect_raise(conn, error),\n\u001b[1;32m    550\u001b[0m     )\n",
      "File \u001b[0;32m/usr/local/lib/python3.10/dist-packages/redis/connection.py:1109\u001b[0m, in \u001b[0;36mConnectionPool.get_connection\u001b[0;34m(self, command_name, *keys, **options)\u001b[0m\n\u001b[1;32m   1105\u001b[0m     \u001b[38;5;28mself\u001b[39m\u001b[38;5;241m.\u001b[39m_in_use_connections\u001b[38;5;241m.\u001b[39madd(connection)\n\u001b[1;32m   1107\u001b[0m \u001b[38;5;28;01mtry\u001b[39;00m:\n\u001b[1;32m   1108\u001b[0m     \u001b[38;5;66;03m# ensure this connection is connected to Redis\u001b[39;00m\n\u001b[0;32m-> 1109\u001b[0m     \u001b[43mconnection\u001b[49m\u001b[38;5;241;43m.\u001b[39;49m\u001b[43mconnect\u001b[49m\u001b[43m(\u001b[49m\u001b[43m)\u001b[49m\n\u001b[1;32m   1110\u001b[0m     \u001b[38;5;66;03m# connections that the pool provides should be ready to send\u001b[39;00m\n\u001b[1;32m   1111\u001b[0m     \u001b[38;5;66;03m# a command. if not, the connection was either returned to the\u001b[39;00m\n\u001b[1;32m   1112\u001b[0m     \u001b[38;5;66;03m# pool before all data has been read or the socket has been\u001b[39;00m\n\u001b[1;32m   1113\u001b[0m     \u001b[38;5;66;03m# closed. either way, reconnect and verify everything is good.\u001b[39;00m\n\u001b[1;32m   1114\u001b[0m     \u001b[38;5;28;01mtry\u001b[39;00m:\n",
      "File \u001b[0;32m/usr/local/lib/python3.10/dist-packages/redis/connection.py:282\u001b[0m, in \u001b[0;36mAbstractConnection.connect\u001b[0;34m(self)\u001b[0m\n\u001b[1;32m    280\u001b[0m     \u001b[38;5;28;01mraise\u001b[39;00m \u001b[38;5;167;01mTimeoutError\u001b[39;00m(\u001b[38;5;124m\"\u001b[39m\u001b[38;5;124mTimeout connecting to server\u001b[39m\u001b[38;5;124m\"\u001b[39m)\n\u001b[1;32m    281\u001b[0m \u001b[38;5;28;01mexcept\u001b[39;00m \u001b[38;5;167;01mOSError\u001b[39;00m \u001b[38;5;28;01mas\u001b[39;00m e:\n\u001b[0;32m--> 282\u001b[0m     \u001b[38;5;28;01mraise\u001b[39;00m \u001b[38;5;167;01mConnectionError\u001b[39;00m(\u001b[38;5;28mself\u001b[39m\u001b[38;5;241m.\u001b[39m_error_message(e))\n\u001b[1;32m    284\u001b[0m \u001b[38;5;28mself\u001b[39m\u001b[38;5;241m.\u001b[39m_sock \u001b[38;5;241m=\u001b[39m sock\n\u001b[1;32m    285\u001b[0m \u001b[38;5;28;01mtry\u001b[39;00m:\n",
      "\u001b[0;31mConnectionError\u001b[0m: Error 111 connecting to localhost:6379. Connection refused."
     ]
    }
   ],
   "source": [
    "# Insert sample data\n",
    "redis_client.set('name', 'Ani')\n",
    "redis_client.set('age', 20)"
   ]
  },
  {
   "cell_type": "markdown",
   "metadata": {},
   "source": [
    "QUERY DATA"
   ]
  },
  {
   "cell_type": "code",
   "execution_count": 6,
   "metadata": {},
   "outputs": [
    {
     "ename": "ConnectionError",
     "evalue": "Error 111 connecting to localhost:6379. Connection refused.",
     "output_type": "error",
     "traceback": [
      "\u001b[0;31m---------------------------------------------------------------------------\u001b[0m",
      "\u001b[0;31mConnectionRefusedError\u001b[0m                    Traceback (most recent call last)",
      "File \u001b[0;32m/usr/local/lib/python3.10/dist-packages/redis/connection.py:276\u001b[0m, in \u001b[0;36mAbstractConnection.connect\u001b[0;34m(self)\u001b[0m\n\u001b[1;32m    275\u001b[0m \u001b[38;5;28;01mtry\u001b[39;00m:\n\u001b[0;32m--> 276\u001b[0m     sock \u001b[38;5;241m=\u001b[39m \u001b[38;5;28;43mself\u001b[39;49m\u001b[38;5;241;43m.\u001b[39;49m\u001b[43mretry\u001b[49m\u001b[38;5;241;43m.\u001b[39;49m\u001b[43mcall_with_retry\u001b[49m\u001b[43m(\u001b[49m\n\u001b[1;32m    277\u001b[0m \u001b[43m        \u001b[49m\u001b[38;5;28;43;01mlambda\u001b[39;49;00m\u001b[43m:\u001b[49m\u001b[43m \u001b[49m\u001b[38;5;28;43mself\u001b[39;49m\u001b[38;5;241;43m.\u001b[39;49m\u001b[43m_connect\u001b[49m\u001b[43m(\u001b[49m\u001b[43m)\u001b[49m\u001b[43m,\u001b[49m\u001b[43m \u001b[49m\u001b[38;5;28;43;01mlambda\u001b[39;49;00m\u001b[43m \u001b[49m\u001b[43merror\u001b[49m\u001b[43m:\u001b[49m\u001b[43m \u001b[49m\u001b[38;5;28;43mself\u001b[39;49m\u001b[38;5;241;43m.\u001b[39;49m\u001b[43mdisconnect\u001b[49m\u001b[43m(\u001b[49m\u001b[43merror\u001b[49m\u001b[43m)\u001b[49m\n\u001b[1;32m    278\u001b[0m \u001b[43m    \u001b[49m\u001b[43m)\u001b[49m\n\u001b[1;32m    279\u001b[0m \u001b[38;5;28;01mexcept\u001b[39;00m socket\u001b[38;5;241m.\u001b[39mtimeout:\n",
      "File \u001b[0;32m/usr/local/lib/python3.10/dist-packages/redis/retry.py:46\u001b[0m, in \u001b[0;36mRetry.call_with_retry\u001b[0;34m(self, do, fail)\u001b[0m\n\u001b[1;32m     45\u001b[0m \u001b[38;5;28;01mtry\u001b[39;00m:\n\u001b[0;32m---> 46\u001b[0m     \u001b[38;5;28;01mreturn\u001b[39;00m \u001b[43mdo\u001b[49m\u001b[43m(\u001b[49m\u001b[43m)\u001b[49m\n\u001b[1;32m     47\u001b[0m \u001b[38;5;28;01mexcept\u001b[39;00m \u001b[38;5;28mself\u001b[39m\u001b[38;5;241m.\u001b[39m_supported_errors \u001b[38;5;28;01mas\u001b[39;00m error:\n",
      "File \u001b[0;32m/usr/local/lib/python3.10/dist-packages/redis/connection.py:277\u001b[0m, in \u001b[0;36mAbstractConnection.connect.<locals>.<lambda>\u001b[0;34m()\u001b[0m\n\u001b[1;32m    275\u001b[0m \u001b[38;5;28;01mtry\u001b[39;00m:\n\u001b[1;32m    276\u001b[0m     sock \u001b[38;5;241m=\u001b[39m \u001b[38;5;28mself\u001b[39m\u001b[38;5;241m.\u001b[39mretry\u001b[38;5;241m.\u001b[39mcall_with_retry(\n\u001b[0;32m--> 277\u001b[0m         \u001b[38;5;28;01mlambda\u001b[39;00m: \u001b[38;5;28;43mself\u001b[39;49m\u001b[38;5;241;43m.\u001b[39;49m\u001b[43m_connect\u001b[49m\u001b[43m(\u001b[49m\u001b[43m)\u001b[49m, \u001b[38;5;28;01mlambda\u001b[39;00m error: \u001b[38;5;28mself\u001b[39m\u001b[38;5;241m.\u001b[39mdisconnect(error)\n\u001b[1;32m    278\u001b[0m     )\n\u001b[1;32m    279\u001b[0m \u001b[38;5;28;01mexcept\u001b[39;00m socket\u001b[38;5;241m.\u001b[39mtimeout:\n",
      "File \u001b[0;32m/usr/local/lib/python3.10/dist-packages/redis/connection.py:639\u001b[0m, in \u001b[0;36mConnection._connect\u001b[0;34m(self)\u001b[0m\n\u001b[1;32m    638\u001b[0m \u001b[38;5;28;01mif\u001b[39;00m err \u001b[38;5;129;01mis\u001b[39;00m \u001b[38;5;129;01mnot\u001b[39;00m \u001b[38;5;28;01mNone\u001b[39;00m:\n\u001b[0;32m--> 639\u001b[0m     \u001b[38;5;28;01mraise\u001b[39;00m err\n\u001b[1;32m    640\u001b[0m \u001b[38;5;28;01mraise\u001b[39;00m \u001b[38;5;167;01mOSError\u001b[39;00m(\u001b[38;5;124m\"\u001b[39m\u001b[38;5;124msocket.getaddrinfo returned an empty list\u001b[39m\u001b[38;5;124m\"\u001b[39m)\n",
      "File \u001b[0;32m/usr/local/lib/python3.10/dist-packages/redis/connection.py:627\u001b[0m, in \u001b[0;36mConnection._connect\u001b[0;34m(self)\u001b[0m\n\u001b[1;32m    626\u001b[0m \u001b[38;5;66;03m# connect\u001b[39;00m\n\u001b[0;32m--> 627\u001b[0m \u001b[43msock\u001b[49m\u001b[38;5;241;43m.\u001b[39;49m\u001b[43mconnect\u001b[49m\u001b[43m(\u001b[49m\u001b[43msocket_address\u001b[49m\u001b[43m)\u001b[49m\n\u001b[1;32m    629\u001b[0m \u001b[38;5;66;03m# set the socket_timeout now that we're connected\u001b[39;00m\n",
      "\u001b[0;31mConnectionRefusedError\u001b[0m: [Errno 111] Connection refused",
      "\nDuring handling of the above exception, another exception occurred:\n",
      "\u001b[0;31mConnectionError\u001b[0m                           Traceback (most recent call last)",
      "Cell \u001b[0;32mIn[6], line 1\u001b[0m\n\u001b[0;32m----> 1\u001b[0m name \u001b[38;5;241m=\u001b[39m \u001b[43mredis_client\u001b[49m\u001b[38;5;241;43m.\u001b[39;49m\u001b[43mget\u001b[49m\u001b[43m(\u001b[49m\u001b[38;5;124;43m'\u001b[39;49m\u001b[38;5;124;43mname\u001b[39;49m\u001b[38;5;124;43m'\u001b[39;49m\u001b[43m)\u001b[49m\u001b[38;5;241m.\u001b[39mdecode(\u001b[38;5;124m'\u001b[39m\u001b[38;5;124mutf-8\u001b[39m\u001b[38;5;124m'\u001b[39m)\n\u001b[1;32m      2\u001b[0m age \u001b[38;5;241m=\u001b[39m redis_client\u001b[38;5;241m.\u001b[39mget(\u001b[38;5;124m'\u001b[39m\u001b[38;5;124mage\u001b[39m\u001b[38;5;124m'\u001b[39m)\u001b[38;5;241m.\u001b[39mdecode(\u001b[38;5;124m'\u001b[39m\u001b[38;5;124mutf-8\u001b[39m\u001b[38;5;124m'\u001b[39m)\n\u001b[1;32m      4\u001b[0m \u001b[38;5;28mprint\u001b[39m(\u001b[38;5;124m\"\u001b[39m\u001b[38;5;124mName:\u001b[39m\u001b[38;5;124m\"\u001b[39m, name)\n",
      "File \u001b[0;32m/usr/local/lib/python3.10/dist-packages/redis/commands/core.py:1830\u001b[0m, in \u001b[0;36mBasicKeyCommands.get\u001b[0;34m(self, name)\u001b[0m\n\u001b[1;32m   1824\u001b[0m \u001b[38;5;28;01mdef\u001b[39;00m \u001b[38;5;21mget\u001b[39m(\u001b[38;5;28mself\u001b[39m, name: KeyT) \u001b[38;5;241m-\u001b[39m\u001b[38;5;241m>\u001b[39m ResponseT:\n\u001b[1;32m   1825\u001b[0m \u001b[38;5;250m    \u001b[39m\u001b[38;5;124;03m\"\"\"\u001b[39;00m\n\u001b[1;32m   1826\u001b[0m \u001b[38;5;124;03m    Return the value at key ``name``, or None if the key doesn't exist\u001b[39;00m\n\u001b[1;32m   1827\u001b[0m \n\u001b[1;32m   1828\u001b[0m \u001b[38;5;124;03m    For more information see https://redis.io/commands/get\u001b[39;00m\n\u001b[1;32m   1829\u001b[0m \u001b[38;5;124;03m    \"\"\"\u001b[39;00m\n\u001b[0;32m-> 1830\u001b[0m     \u001b[38;5;28;01mreturn\u001b[39;00m \u001b[38;5;28;43mself\u001b[39;49m\u001b[38;5;241;43m.\u001b[39;49m\u001b[43mexecute_command\u001b[49m\u001b[43m(\u001b[49m\u001b[38;5;124;43m\"\u001b[39;49m\u001b[38;5;124;43mGET\u001b[39;49m\u001b[38;5;124;43m\"\u001b[39;49m\u001b[43m,\u001b[49m\u001b[43m \u001b[49m\u001b[43mname\u001b[49m\u001b[43m)\u001b[49m\n",
      "File \u001b[0;32m/usr/local/lib/python3.10/dist-packages/redis/client.py:542\u001b[0m, in \u001b[0;36mRedis.execute_command\u001b[0;34m(self, *args, **options)\u001b[0m\n\u001b[1;32m    540\u001b[0m pool \u001b[38;5;241m=\u001b[39m \u001b[38;5;28mself\u001b[39m\u001b[38;5;241m.\u001b[39mconnection_pool\n\u001b[1;32m    541\u001b[0m command_name \u001b[38;5;241m=\u001b[39m args[\u001b[38;5;241m0\u001b[39m]\n\u001b[0;32m--> 542\u001b[0m conn \u001b[38;5;241m=\u001b[39m \u001b[38;5;28mself\u001b[39m\u001b[38;5;241m.\u001b[39mconnection \u001b[38;5;129;01mor\u001b[39;00m \u001b[43mpool\u001b[49m\u001b[38;5;241;43m.\u001b[39;49m\u001b[43mget_connection\u001b[49m\u001b[43m(\u001b[49m\u001b[43mcommand_name\u001b[49m\u001b[43m,\u001b[49m\u001b[43m \u001b[49m\u001b[38;5;241;43m*\u001b[39;49m\u001b[38;5;241;43m*\u001b[39;49m\u001b[43moptions\u001b[49m\u001b[43m)\u001b[49m\n\u001b[1;32m    544\u001b[0m \u001b[38;5;28;01mtry\u001b[39;00m:\n\u001b[1;32m    545\u001b[0m     \u001b[38;5;28;01mreturn\u001b[39;00m conn\u001b[38;5;241m.\u001b[39mretry\u001b[38;5;241m.\u001b[39mcall_with_retry(\n\u001b[1;32m    546\u001b[0m         \u001b[38;5;28;01mlambda\u001b[39;00m: \u001b[38;5;28mself\u001b[39m\u001b[38;5;241m.\u001b[39m_send_command_parse_response(\n\u001b[1;32m    547\u001b[0m             conn, command_name, \u001b[38;5;241m*\u001b[39margs, \u001b[38;5;241m*\u001b[39m\u001b[38;5;241m*\u001b[39moptions\n\u001b[1;32m    548\u001b[0m         ),\n\u001b[1;32m    549\u001b[0m         \u001b[38;5;28;01mlambda\u001b[39;00m error: \u001b[38;5;28mself\u001b[39m\u001b[38;5;241m.\u001b[39m_disconnect_raise(conn, error),\n\u001b[1;32m    550\u001b[0m     )\n",
      "File \u001b[0;32m/usr/local/lib/python3.10/dist-packages/redis/connection.py:1109\u001b[0m, in \u001b[0;36mConnectionPool.get_connection\u001b[0;34m(self, command_name, *keys, **options)\u001b[0m\n\u001b[1;32m   1105\u001b[0m     \u001b[38;5;28mself\u001b[39m\u001b[38;5;241m.\u001b[39m_in_use_connections\u001b[38;5;241m.\u001b[39madd(connection)\n\u001b[1;32m   1107\u001b[0m \u001b[38;5;28;01mtry\u001b[39;00m:\n\u001b[1;32m   1108\u001b[0m     \u001b[38;5;66;03m# ensure this connection is connected to Redis\u001b[39;00m\n\u001b[0;32m-> 1109\u001b[0m     \u001b[43mconnection\u001b[49m\u001b[38;5;241;43m.\u001b[39;49m\u001b[43mconnect\u001b[49m\u001b[43m(\u001b[49m\u001b[43m)\u001b[49m\n\u001b[1;32m   1110\u001b[0m     \u001b[38;5;66;03m# connections that the pool provides should be ready to send\u001b[39;00m\n\u001b[1;32m   1111\u001b[0m     \u001b[38;5;66;03m# a command. if not, the connection was either returned to the\u001b[39;00m\n\u001b[1;32m   1112\u001b[0m     \u001b[38;5;66;03m# pool before all data has been read or the socket has been\u001b[39;00m\n\u001b[1;32m   1113\u001b[0m     \u001b[38;5;66;03m# closed. either way, reconnect and verify everything is good.\u001b[39;00m\n\u001b[1;32m   1114\u001b[0m     \u001b[38;5;28;01mtry\u001b[39;00m:\n",
      "File \u001b[0;32m/usr/local/lib/python3.10/dist-packages/redis/connection.py:282\u001b[0m, in \u001b[0;36mAbstractConnection.connect\u001b[0;34m(self)\u001b[0m\n\u001b[1;32m    280\u001b[0m     \u001b[38;5;28;01mraise\u001b[39;00m \u001b[38;5;167;01mTimeoutError\u001b[39;00m(\u001b[38;5;124m\"\u001b[39m\u001b[38;5;124mTimeout connecting to server\u001b[39m\u001b[38;5;124m\"\u001b[39m)\n\u001b[1;32m    281\u001b[0m \u001b[38;5;28;01mexcept\u001b[39;00m \u001b[38;5;167;01mOSError\u001b[39;00m \u001b[38;5;28;01mas\u001b[39;00m e:\n\u001b[0;32m--> 282\u001b[0m     \u001b[38;5;28;01mraise\u001b[39;00m \u001b[38;5;167;01mConnectionError\u001b[39;00m(\u001b[38;5;28mself\u001b[39m\u001b[38;5;241m.\u001b[39m_error_message(e))\n\u001b[1;32m    284\u001b[0m \u001b[38;5;28mself\u001b[39m\u001b[38;5;241m.\u001b[39m_sock \u001b[38;5;241m=\u001b[39m sock\n\u001b[1;32m    285\u001b[0m \u001b[38;5;28;01mtry\u001b[39;00m:\n",
      "\u001b[0;31mConnectionError\u001b[0m: Error 111 connecting to localhost:6379. Connection refused."
     ]
    }
   ],
   "source": [
    "name = redis_client.get('name').decode('utf-8')\n",
    "age = redis_client.get('age').decode('utf-8')\n",
    "\n",
    "print(\"Name:\", name)\n",
    "print(\"Age:\", age)"
   ]
  },
  {
   "cell_type": "markdown",
   "metadata": {},
   "source": [
    "INSERT MULTI"
   ]
  },
  {
   "cell_type": "code",
   "execution_count": 6,
   "metadata": {},
   "outputs": [
    {
     "ename": "ConnectionError",
     "evalue": "Error 111 connecting to localhost:6379. Connection refused.",
     "output_type": "error",
     "traceback": [
      "\u001b[0;31m---------------------------------------------------------------------------\u001b[0m",
      "\u001b[0;31mConnectionRefusedError\u001b[0m                    Traceback (most recent call last)",
      "File \u001b[0;32m/usr/local/lib/python3.10/dist-packages/redis/connection.py:276\u001b[0m, in \u001b[0;36mAbstractConnection.connect\u001b[0;34m(self)\u001b[0m\n\u001b[1;32m    275\u001b[0m \u001b[38;5;28;01mtry\u001b[39;00m:\n\u001b[0;32m--> 276\u001b[0m     sock \u001b[38;5;241m=\u001b[39m \u001b[38;5;28;43mself\u001b[39;49m\u001b[38;5;241;43m.\u001b[39;49m\u001b[43mretry\u001b[49m\u001b[38;5;241;43m.\u001b[39;49m\u001b[43mcall_with_retry\u001b[49m\u001b[43m(\u001b[49m\n\u001b[1;32m    277\u001b[0m \u001b[43m        \u001b[49m\u001b[38;5;28;43;01mlambda\u001b[39;49;00m\u001b[43m:\u001b[49m\u001b[43m \u001b[49m\u001b[38;5;28;43mself\u001b[39;49m\u001b[38;5;241;43m.\u001b[39;49m\u001b[43m_connect\u001b[49m\u001b[43m(\u001b[49m\u001b[43m)\u001b[49m\u001b[43m,\u001b[49m\u001b[43m \u001b[49m\u001b[38;5;28;43;01mlambda\u001b[39;49;00m\u001b[43m \u001b[49m\u001b[43merror\u001b[49m\u001b[43m:\u001b[49m\u001b[43m \u001b[49m\u001b[38;5;28;43mself\u001b[39;49m\u001b[38;5;241;43m.\u001b[39;49m\u001b[43mdisconnect\u001b[49m\u001b[43m(\u001b[49m\u001b[43merror\u001b[49m\u001b[43m)\u001b[49m\n\u001b[1;32m    278\u001b[0m \u001b[43m    \u001b[49m\u001b[43m)\u001b[49m\n\u001b[1;32m    279\u001b[0m \u001b[38;5;28;01mexcept\u001b[39;00m socket\u001b[38;5;241m.\u001b[39mtimeout:\n",
      "File \u001b[0;32m/usr/local/lib/python3.10/dist-packages/redis/retry.py:46\u001b[0m, in \u001b[0;36mRetry.call_with_retry\u001b[0;34m(self, do, fail)\u001b[0m\n\u001b[1;32m     45\u001b[0m \u001b[38;5;28;01mtry\u001b[39;00m:\n\u001b[0;32m---> 46\u001b[0m     \u001b[38;5;28;01mreturn\u001b[39;00m \u001b[43mdo\u001b[49m\u001b[43m(\u001b[49m\u001b[43m)\u001b[49m\n\u001b[1;32m     47\u001b[0m \u001b[38;5;28;01mexcept\u001b[39;00m \u001b[38;5;28mself\u001b[39m\u001b[38;5;241m.\u001b[39m_supported_errors \u001b[38;5;28;01mas\u001b[39;00m error:\n",
      "File \u001b[0;32m/usr/local/lib/python3.10/dist-packages/redis/connection.py:277\u001b[0m, in \u001b[0;36mAbstractConnection.connect.<locals>.<lambda>\u001b[0;34m()\u001b[0m\n\u001b[1;32m    275\u001b[0m \u001b[38;5;28;01mtry\u001b[39;00m:\n\u001b[1;32m    276\u001b[0m     sock \u001b[38;5;241m=\u001b[39m \u001b[38;5;28mself\u001b[39m\u001b[38;5;241m.\u001b[39mretry\u001b[38;5;241m.\u001b[39mcall_with_retry(\n\u001b[0;32m--> 277\u001b[0m         \u001b[38;5;28;01mlambda\u001b[39;00m: \u001b[38;5;28;43mself\u001b[39;49m\u001b[38;5;241;43m.\u001b[39;49m\u001b[43m_connect\u001b[49m\u001b[43m(\u001b[49m\u001b[43m)\u001b[49m, \u001b[38;5;28;01mlambda\u001b[39;00m error: \u001b[38;5;28mself\u001b[39m\u001b[38;5;241m.\u001b[39mdisconnect(error)\n\u001b[1;32m    278\u001b[0m     )\n\u001b[1;32m    279\u001b[0m \u001b[38;5;28;01mexcept\u001b[39;00m socket\u001b[38;5;241m.\u001b[39mtimeout:\n",
      "File \u001b[0;32m/usr/local/lib/python3.10/dist-packages/redis/connection.py:639\u001b[0m, in \u001b[0;36mConnection._connect\u001b[0;34m(self)\u001b[0m\n\u001b[1;32m    638\u001b[0m \u001b[38;5;28;01mif\u001b[39;00m err \u001b[38;5;129;01mis\u001b[39;00m \u001b[38;5;129;01mnot\u001b[39;00m \u001b[38;5;28;01mNone\u001b[39;00m:\n\u001b[0;32m--> 639\u001b[0m     \u001b[38;5;28;01mraise\u001b[39;00m err\n\u001b[1;32m    640\u001b[0m \u001b[38;5;28;01mraise\u001b[39;00m \u001b[38;5;167;01mOSError\u001b[39;00m(\u001b[38;5;124m\"\u001b[39m\u001b[38;5;124msocket.getaddrinfo returned an empty list\u001b[39m\u001b[38;5;124m\"\u001b[39m)\n",
      "File \u001b[0;32m/usr/local/lib/python3.10/dist-packages/redis/connection.py:627\u001b[0m, in \u001b[0;36mConnection._connect\u001b[0;34m(self)\u001b[0m\n\u001b[1;32m    626\u001b[0m \u001b[38;5;66;03m# connect\u001b[39;00m\n\u001b[0;32m--> 627\u001b[0m \u001b[43msock\u001b[49m\u001b[38;5;241;43m.\u001b[39;49m\u001b[43mconnect\u001b[49m\u001b[43m(\u001b[49m\u001b[43msocket_address\u001b[49m\u001b[43m)\u001b[49m\n\u001b[1;32m    629\u001b[0m \u001b[38;5;66;03m# set the socket_timeout now that we're connected\u001b[39;00m\n",
      "\u001b[0;31mConnectionRefusedError\u001b[0m: [Errno 111] Connection refused",
      "\nDuring handling of the above exception, another exception occurred:\n",
      "\u001b[0;31mConnectionError\u001b[0m                           Traceback (most recent call last)",
      "Cell \u001b[0;32mIn[6], line 8\u001b[0m\n\u001b[1;32m      1\u001b[0m \u001b[38;5;66;03m# Insert multiple key-value pairs\u001b[39;00m\n\u001b[1;32m      2\u001b[0m data \u001b[38;5;241m=\u001b[39m {\n\u001b[1;32m      3\u001b[0m     \u001b[38;5;124m'\u001b[39m\u001b[38;5;124mname1\u001b[39m\u001b[38;5;124m'\u001b[39m: \u001b[38;5;124m'\u001b[39m\u001b[38;5;124mBudi\u001b[39m\u001b[38;5;124m'\u001b[39m,\n\u001b[1;32m      4\u001b[0m     \u001b[38;5;124m'\u001b[39m\u001b[38;5;124mname2\u001b[39m\u001b[38;5;124m'\u001b[39m: \u001b[38;5;124m'\u001b[39m\u001b[38;5;124mCaca\u001b[39m\u001b[38;5;124m'\u001b[39m,\n\u001b[1;32m      5\u001b[0m     \u001b[38;5;124m'\u001b[39m\u001b[38;5;124mage1\u001b[39m\u001b[38;5;124m'\u001b[39m: \u001b[38;5;241m21\u001b[39m,\n\u001b[1;32m      6\u001b[0m     \u001b[38;5;124m'\u001b[39m\u001b[38;5;124mage2\u001b[39m\u001b[38;5;124m'\u001b[39m: \u001b[38;5;241m20\u001b[39m\n\u001b[1;32m      7\u001b[0m }\n\u001b[0;32m----> 8\u001b[0m \u001b[43mredis_client\u001b[49m\u001b[38;5;241;43m.\u001b[39;49m\u001b[43mmset\u001b[49m\u001b[43m(\u001b[49m\u001b[43mdata\u001b[49m\u001b[43m)\u001b[49m\n",
      "File \u001b[0;32m/usr/local/lib/python3.10/dist-packages/redis/commands/core.py:2029\u001b[0m, in \u001b[0;36mBasicKeyCommands.mset\u001b[0;34m(self, mapping)\u001b[0m\n\u001b[1;32m   2027\u001b[0m \u001b[38;5;28;01mfor\u001b[39;00m pair \u001b[38;5;129;01min\u001b[39;00m mapping\u001b[38;5;241m.\u001b[39mitems():\n\u001b[1;32m   2028\u001b[0m     items\u001b[38;5;241m.\u001b[39mextend(pair)\n\u001b[0;32m-> 2029\u001b[0m \u001b[38;5;28;01mreturn\u001b[39;00m \u001b[38;5;28;43mself\u001b[39;49m\u001b[38;5;241;43m.\u001b[39;49m\u001b[43mexecute_command\u001b[49m\u001b[43m(\u001b[49m\u001b[38;5;124;43m\"\u001b[39;49m\u001b[38;5;124;43mMSET\u001b[39;49m\u001b[38;5;124;43m\"\u001b[39;49m\u001b[43m,\u001b[49m\u001b[43m \u001b[49m\u001b[38;5;241;43m*\u001b[39;49m\u001b[43mitems\u001b[49m\u001b[43m)\u001b[49m\n",
      "File \u001b[0;32m/usr/local/lib/python3.10/dist-packages/redis/client.py:542\u001b[0m, in \u001b[0;36mRedis.execute_command\u001b[0;34m(self, *args, **options)\u001b[0m\n\u001b[1;32m    540\u001b[0m pool \u001b[38;5;241m=\u001b[39m \u001b[38;5;28mself\u001b[39m\u001b[38;5;241m.\u001b[39mconnection_pool\n\u001b[1;32m    541\u001b[0m command_name \u001b[38;5;241m=\u001b[39m args[\u001b[38;5;241m0\u001b[39m]\n\u001b[0;32m--> 542\u001b[0m conn \u001b[38;5;241m=\u001b[39m \u001b[38;5;28mself\u001b[39m\u001b[38;5;241m.\u001b[39mconnection \u001b[38;5;129;01mor\u001b[39;00m \u001b[43mpool\u001b[49m\u001b[38;5;241;43m.\u001b[39;49m\u001b[43mget_connection\u001b[49m\u001b[43m(\u001b[49m\u001b[43mcommand_name\u001b[49m\u001b[43m,\u001b[49m\u001b[43m \u001b[49m\u001b[38;5;241;43m*\u001b[39;49m\u001b[38;5;241;43m*\u001b[39;49m\u001b[43moptions\u001b[49m\u001b[43m)\u001b[49m\n\u001b[1;32m    544\u001b[0m \u001b[38;5;28;01mtry\u001b[39;00m:\n\u001b[1;32m    545\u001b[0m     \u001b[38;5;28;01mreturn\u001b[39;00m conn\u001b[38;5;241m.\u001b[39mretry\u001b[38;5;241m.\u001b[39mcall_with_retry(\n\u001b[1;32m    546\u001b[0m         \u001b[38;5;28;01mlambda\u001b[39;00m: \u001b[38;5;28mself\u001b[39m\u001b[38;5;241m.\u001b[39m_send_command_parse_response(\n\u001b[1;32m    547\u001b[0m             conn, command_name, \u001b[38;5;241m*\u001b[39margs, \u001b[38;5;241m*\u001b[39m\u001b[38;5;241m*\u001b[39moptions\n\u001b[1;32m    548\u001b[0m         ),\n\u001b[1;32m    549\u001b[0m         \u001b[38;5;28;01mlambda\u001b[39;00m error: \u001b[38;5;28mself\u001b[39m\u001b[38;5;241m.\u001b[39m_disconnect_raise(conn, error),\n\u001b[1;32m    550\u001b[0m     )\n",
      "File \u001b[0;32m/usr/local/lib/python3.10/dist-packages/redis/connection.py:1109\u001b[0m, in \u001b[0;36mConnectionPool.get_connection\u001b[0;34m(self, command_name, *keys, **options)\u001b[0m\n\u001b[1;32m   1105\u001b[0m     \u001b[38;5;28mself\u001b[39m\u001b[38;5;241m.\u001b[39m_in_use_connections\u001b[38;5;241m.\u001b[39madd(connection)\n\u001b[1;32m   1107\u001b[0m \u001b[38;5;28;01mtry\u001b[39;00m:\n\u001b[1;32m   1108\u001b[0m     \u001b[38;5;66;03m# ensure this connection is connected to Redis\u001b[39;00m\n\u001b[0;32m-> 1109\u001b[0m     \u001b[43mconnection\u001b[49m\u001b[38;5;241;43m.\u001b[39;49m\u001b[43mconnect\u001b[49m\u001b[43m(\u001b[49m\u001b[43m)\u001b[49m\n\u001b[1;32m   1110\u001b[0m     \u001b[38;5;66;03m# connections that the pool provides should be ready to send\u001b[39;00m\n\u001b[1;32m   1111\u001b[0m     \u001b[38;5;66;03m# a command. if not, the connection was either returned to the\u001b[39;00m\n\u001b[1;32m   1112\u001b[0m     \u001b[38;5;66;03m# pool before all data has been read or the socket has been\u001b[39;00m\n\u001b[1;32m   1113\u001b[0m     \u001b[38;5;66;03m# closed. either way, reconnect and verify everything is good.\u001b[39;00m\n\u001b[1;32m   1114\u001b[0m     \u001b[38;5;28;01mtry\u001b[39;00m:\n",
      "File \u001b[0;32m/usr/local/lib/python3.10/dist-packages/redis/connection.py:282\u001b[0m, in \u001b[0;36mAbstractConnection.connect\u001b[0;34m(self)\u001b[0m\n\u001b[1;32m    280\u001b[0m     \u001b[38;5;28;01mraise\u001b[39;00m \u001b[38;5;167;01mTimeoutError\u001b[39;00m(\u001b[38;5;124m\"\u001b[39m\u001b[38;5;124mTimeout connecting to server\u001b[39m\u001b[38;5;124m\"\u001b[39m)\n\u001b[1;32m    281\u001b[0m \u001b[38;5;28;01mexcept\u001b[39;00m \u001b[38;5;167;01mOSError\u001b[39;00m \u001b[38;5;28;01mas\u001b[39;00m e:\n\u001b[0;32m--> 282\u001b[0m     \u001b[38;5;28;01mraise\u001b[39;00m \u001b[38;5;167;01mConnectionError\u001b[39;00m(\u001b[38;5;28mself\u001b[39m\u001b[38;5;241m.\u001b[39m_error_message(e))\n\u001b[1;32m    284\u001b[0m \u001b[38;5;28mself\u001b[39m\u001b[38;5;241m.\u001b[39m_sock \u001b[38;5;241m=\u001b[39m sock\n\u001b[1;32m    285\u001b[0m \u001b[38;5;28;01mtry\u001b[39;00m:\n",
      "\u001b[0;31mConnectionError\u001b[0m: Error 111 connecting to localhost:6379. Connection refused."
     ]
    }
   ],
   "source": [
    "# Insert multiple key-value pairs\n",
    "data = {\n",
    "    'name1': 'Budi',\n",
    "    'name2': 'Caca',\n",
    "    'age1': 21,\n",
    "    'age2': 20\n",
    "}\n",
    "redis_client.mset(data)"
   ]
  },
  {
   "cell_type": "markdown",
   "metadata": {},
   "source": [
    "QUERY DATA"
   ]
  },
  {
   "cell_type": "code",
   "execution_count": 7,
   "metadata": {},
   "outputs": [
    {
     "ename": "ConnectionError",
     "evalue": "Error 111 connecting to localhost:6379. Connection refused.",
     "output_type": "error",
     "traceback": [
      "\u001b[0;31m---------------------------------------------------------------------------\u001b[0m",
      "\u001b[0;31mConnectionRefusedError\u001b[0m                    Traceback (most recent call last)",
      "File \u001b[0;32m/usr/local/lib/python3.10/dist-packages/redis/connection.py:276\u001b[0m, in \u001b[0;36mAbstractConnection.connect\u001b[0;34m(self)\u001b[0m\n\u001b[1;32m    275\u001b[0m \u001b[38;5;28;01mtry\u001b[39;00m:\n\u001b[0;32m--> 276\u001b[0m     sock \u001b[38;5;241m=\u001b[39m \u001b[38;5;28;43mself\u001b[39;49m\u001b[38;5;241;43m.\u001b[39;49m\u001b[43mretry\u001b[49m\u001b[38;5;241;43m.\u001b[39;49m\u001b[43mcall_with_retry\u001b[49m\u001b[43m(\u001b[49m\n\u001b[1;32m    277\u001b[0m \u001b[43m        \u001b[49m\u001b[38;5;28;43;01mlambda\u001b[39;49;00m\u001b[43m:\u001b[49m\u001b[43m \u001b[49m\u001b[38;5;28;43mself\u001b[39;49m\u001b[38;5;241;43m.\u001b[39;49m\u001b[43m_connect\u001b[49m\u001b[43m(\u001b[49m\u001b[43m)\u001b[49m\u001b[43m,\u001b[49m\u001b[43m \u001b[49m\u001b[38;5;28;43;01mlambda\u001b[39;49;00m\u001b[43m \u001b[49m\u001b[43merror\u001b[49m\u001b[43m:\u001b[49m\u001b[43m \u001b[49m\u001b[38;5;28;43mself\u001b[39;49m\u001b[38;5;241;43m.\u001b[39;49m\u001b[43mdisconnect\u001b[49m\u001b[43m(\u001b[49m\u001b[43merror\u001b[49m\u001b[43m)\u001b[49m\n\u001b[1;32m    278\u001b[0m \u001b[43m    \u001b[49m\u001b[43m)\u001b[49m\n\u001b[1;32m    279\u001b[0m \u001b[38;5;28;01mexcept\u001b[39;00m socket\u001b[38;5;241m.\u001b[39mtimeout:\n",
      "File \u001b[0;32m/usr/local/lib/python3.10/dist-packages/redis/retry.py:46\u001b[0m, in \u001b[0;36mRetry.call_with_retry\u001b[0;34m(self, do, fail)\u001b[0m\n\u001b[1;32m     45\u001b[0m \u001b[38;5;28;01mtry\u001b[39;00m:\n\u001b[0;32m---> 46\u001b[0m     \u001b[38;5;28;01mreturn\u001b[39;00m \u001b[43mdo\u001b[49m\u001b[43m(\u001b[49m\u001b[43m)\u001b[49m\n\u001b[1;32m     47\u001b[0m \u001b[38;5;28;01mexcept\u001b[39;00m \u001b[38;5;28mself\u001b[39m\u001b[38;5;241m.\u001b[39m_supported_errors \u001b[38;5;28;01mas\u001b[39;00m error:\n",
      "File \u001b[0;32m/usr/local/lib/python3.10/dist-packages/redis/connection.py:277\u001b[0m, in \u001b[0;36mAbstractConnection.connect.<locals>.<lambda>\u001b[0;34m()\u001b[0m\n\u001b[1;32m    275\u001b[0m \u001b[38;5;28;01mtry\u001b[39;00m:\n\u001b[1;32m    276\u001b[0m     sock \u001b[38;5;241m=\u001b[39m \u001b[38;5;28mself\u001b[39m\u001b[38;5;241m.\u001b[39mretry\u001b[38;5;241m.\u001b[39mcall_with_retry(\n\u001b[0;32m--> 277\u001b[0m         \u001b[38;5;28;01mlambda\u001b[39;00m: \u001b[38;5;28;43mself\u001b[39;49m\u001b[38;5;241;43m.\u001b[39;49m\u001b[43m_connect\u001b[49m\u001b[43m(\u001b[49m\u001b[43m)\u001b[49m, \u001b[38;5;28;01mlambda\u001b[39;00m error: \u001b[38;5;28mself\u001b[39m\u001b[38;5;241m.\u001b[39mdisconnect(error)\n\u001b[1;32m    278\u001b[0m     )\n\u001b[1;32m    279\u001b[0m \u001b[38;5;28;01mexcept\u001b[39;00m socket\u001b[38;5;241m.\u001b[39mtimeout:\n",
      "File \u001b[0;32m/usr/local/lib/python3.10/dist-packages/redis/connection.py:639\u001b[0m, in \u001b[0;36mConnection._connect\u001b[0;34m(self)\u001b[0m\n\u001b[1;32m    638\u001b[0m \u001b[38;5;28;01mif\u001b[39;00m err \u001b[38;5;129;01mis\u001b[39;00m \u001b[38;5;129;01mnot\u001b[39;00m \u001b[38;5;28;01mNone\u001b[39;00m:\n\u001b[0;32m--> 639\u001b[0m     \u001b[38;5;28;01mraise\u001b[39;00m err\n\u001b[1;32m    640\u001b[0m \u001b[38;5;28;01mraise\u001b[39;00m \u001b[38;5;167;01mOSError\u001b[39;00m(\u001b[38;5;124m\"\u001b[39m\u001b[38;5;124msocket.getaddrinfo returned an empty list\u001b[39m\u001b[38;5;124m\"\u001b[39m)\n",
      "File \u001b[0;32m/usr/local/lib/python3.10/dist-packages/redis/connection.py:627\u001b[0m, in \u001b[0;36mConnection._connect\u001b[0;34m(self)\u001b[0m\n\u001b[1;32m    626\u001b[0m \u001b[38;5;66;03m# connect\u001b[39;00m\n\u001b[0;32m--> 627\u001b[0m \u001b[43msock\u001b[49m\u001b[38;5;241;43m.\u001b[39;49m\u001b[43mconnect\u001b[49m\u001b[43m(\u001b[49m\u001b[43msocket_address\u001b[49m\u001b[43m)\u001b[49m\n\u001b[1;32m    629\u001b[0m \u001b[38;5;66;03m# set the socket_timeout now that we're connected\u001b[39;00m\n",
      "\u001b[0;31mConnectionRefusedError\u001b[0m: [Errno 111] Connection refused",
      "\nDuring handling of the above exception, another exception occurred:\n",
      "\u001b[0;31mConnectionError\u001b[0m                           Traceback (most recent call last)",
      "Cell \u001b[0;32mIn[7], line 2\u001b[0m\n\u001b[1;32m      1\u001b[0m keys \u001b[38;5;241m=\u001b[39m [\u001b[38;5;124m'\u001b[39m\u001b[38;5;124mname\u001b[39m\u001b[38;5;124m'\u001b[39m, \u001b[38;5;124m'\u001b[39m\u001b[38;5;124mname1\u001b[39m\u001b[38;5;124m'\u001b[39m, \u001b[38;5;124m'\u001b[39m\u001b[38;5;124mname2\u001b[39m\u001b[38;5;124m'\u001b[39m,\u001b[38;5;124m'\u001b[39m\u001b[38;5;124mage\u001b[39m\u001b[38;5;124m'\u001b[39m, \u001b[38;5;124m'\u001b[39m\u001b[38;5;124mage1\u001b[39m\u001b[38;5;124m'\u001b[39m, \u001b[38;5;124m'\u001b[39m\u001b[38;5;124mage2\u001b[39m\u001b[38;5;124m'\u001b[39m]\n\u001b[0;32m----> 2\u001b[0m values \u001b[38;5;241m=\u001b[39m \u001b[43mredis_client\u001b[49m\u001b[38;5;241;43m.\u001b[39;49m\u001b[43mmget\u001b[49m\u001b[43m(\u001b[49m\u001b[43mkeys\u001b[49m\u001b[43m)\u001b[49m\n\u001b[1;32m      4\u001b[0m \u001b[38;5;28;01mfor\u001b[39;00m key, value \u001b[38;5;129;01min\u001b[39;00m \u001b[38;5;28mzip\u001b[39m(keys, values):\n\u001b[1;32m      5\u001b[0m     \u001b[38;5;28mprint\u001b[39m(\u001b[38;5;124mf\u001b[39m\u001b[38;5;124m\"\u001b[39m\u001b[38;5;132;01m{\u001b[39;00mkey\u001b[38;5;132;01m}\u001b[39;00m\u001b[38;5;124m: \u001b[39m\u001b[38;5;132;01m{\u001b[39;00mvalue\u001b[38;5;241m.\u001b[39mdecode(\u001b[38;5;124m'\u001b[39m\u001b[38;5;124mutf-8\u001b[39m\u001b[38;5;124m'\u001b[39m)\u001b[38;5;132;01m}\u001b[39;00m\u001b[38;5;124m\"\u001b[39m)\n",
      "File \u001b[0;32m/usr/local/lib/python3.10/dist-packages/redis/commands/core.py:2016\u001b[0m, in \u001b[0;36mBasicKeyCommands.mget\u001b[0;34m(self, keys, *args)\u001b[0m\n\u001b[1;32m   2014\u001b[0m \u001b[38;5;28;01mif\u001b[39;00m \u001b[38;5;129;01mnot\u001b[39;00m args:\n\u001b[1;32m   2015\u001b[0m     options[EMPTY_RESPONSE] \u001b[38;5;241m=\u001b[39m []\n\u001b[0;32m-> 2016\u001b[0m \u001b[38;5;28;01mreturn\u001b[39;00m \u001b[38;5;28;43mself\u001b[39;49m\u001b[38;5;241;43m.\u001b[39;49m\u001b[43mexecute_command\u001b[49m\u001b[43m(\u001b[49m\u001b[38;5;124;43m\"\u001b[39;49m\u001b[38;5;124;43mMGET\u001b[39;49m\u001b[38;5;124;43m\"\u001b[39;49m\u001b[43m,\u001b[49m\u001b[43m \u001b[49m\u001b[38;5;241;43m*\u001b[39;49m\u001b[43margs\u001b[49m\u001b[43m,\u001b[49m\u001b[43m \u001b[49m\u001b[38;5;241;43m*\u001b[39;49m\u001b[38;5;241;43m*\u001b[39;49m\u001b[43moptions\u001b[49m\u001b[43m)\u001b[49m\n",
      "File \u001b[0;32m/usr/local/lib/python3.10/dist-packages/redis/client.py:542\u001b[0m, in \u001b[0;36mRedis.execute_command\u001b[0;34m(self, *args, **options)\u001b[0m\n\u001b[1;32m    540\u001b[0m pool \u001b[38;5;241m=\u001b[39m \u001b[38;5;28mself\u001b[39m\u001b[38;5;241m.\u001b[39mconnection_pool\n\u001b[1;32m    541\u001b[0m command_name \u001b[38;5;241m=\u001b[39m args[\u001b[38;5;241m0\u001b[39m]\n\u001b[0;32m--> 542\u001b[0m conn \u001b[38;5;241m=\u001b[39m \u001b[38;5;28mself\u001b[39m\u001b[38;5;241m.\u001b[39mconnection \u001b[38;5;129;01mor\u001b[39;00m \u001b[43mpool\u001b[49m\u001b[38;5;241;43m.\u001b[39;49m\u001b[43mget_connection\u001b[49m\u001b[43m(\u001b[49m\u001b[43mcommand_name\u001b[49m\u001b[43m,\u001b[49m\u001b[43m \u001b[49m\u001b[38;5;241;43m*\u001b[39;49m\u001b[38;5;241;43m*\u001b[39;49m\u001b[43moptions\u001b[49m\u001b[43m)\u001b[49m\n\u001b[1;32m    544\u001b[0m \u001b[38;5;28;01mtry\u001b[39;00m:\n\u001b[1;32m    545\u001b[0m     \u001b[38;5;28;01mreturn\u001b[39;00m conn\u001b[38;5;241m.\u001b[39mretry\u001b[38;5;241m.\u001b[39mcall_with_retry(\n\u001b[1;32m    546\u001b[0m         \u001b[38;5;28;01mlambda\u001b[39;00m: \u001b[38;5;28mself\u001b[39m\u001b[38;5;241m.\u001b[39m_send_command_parse_response(\n\u001b[1;32m    547\u001b[0m             conn, command_name, \u001b[38;5;241m*\u001b[39margs, \u001b[38;5;241m*\u001b[39m\u001b[38;5;241m*\u001b[39moptions\n\u001b[1;32m    548\u001b[0m         ),\n\u001b[1;32m    549\u001b[0m         \u001b[38;5;28;01mlambda\u001b[39;00m error: \u001b[38;5;28mself\u001b[39m\u001b[38;5;241m.\u001b[39m_disconnect_raise(conn, error),\n\u001b[1;32m    550\u001b[0m     )\n",
      "File \u001b[0;32m/usr/local/lib/python3.10/dist-packages/redis/connection.py:1109\u001b[0m, in \u001b[0;36mConnectionPool.get_connection\u001b[0;34m(self, command_name, *keys, **options)\u001b[0m\n\u001b[1;32m   1105\u001b[0m     \u001b[38;5;28mself\u001b[39m\u001b[38;5;241m.\u001b[39m_in_use_connections\u001b[38;5;241m.\u001b[39madd(connection)\n\u001b[1;32m   1107\u001b[0m \u001b[38;5;28;01mtry\u001b[39;00m:\n\u001b[1;32m   1108\u001b[0m     \u001b[38;5;66;03m# ensure this connection is connected to Redis\u001b[39;00m\n\u001b[0;32m-> 1109\u001b[0m     \u001b[43mconnection\u001b[49m\u001b[38;5;241;43m.\u001b[39;49m\u001b[43mconnect\u001b[49m\u001b[43m(\u001b[49m\u001b[43m)\u001b[49m\n\u001b[1;32m   1110\u001b[0m     \u001b[38;5;66;03m# connections that the pool provides should be ready to send\u001b[39;00m\n\u001b[1;32m   1111\u001b[0m     \u001b[38;5;66;03m# a command. if not, the connection was either returned to the\u001b[39;00m\n\u001b[1;32m   1112\u001b[0m     \u001b[38;5;66;03m# pool before all data has been read or the socket has been\u001b[39;00m\n\u001b[1;32m   1113\u001b[0m     \u001b[38;5;66;03m# closed. either way, reconnect and verify everything is good.\u001b[39;00m\n\u001b[1;32m   1114\u001b[0m     \u001b[38;5;28;01mtry\u001b[39;00m:\n",
      "File \u001b[0;32m/usr/local/lib/python3.10/dist-packages/redis/connection.py:282\u001b[0m, in \u001b[0;36mAbstractConnection.connect\u001b[0;34m(self)\u001b[0m\n\u001b[1;32m    280\u001b[0m     \u001b[38;5;28;01mraise\u001b[39;00m \u001b[38;5;167;01mTimeoutError\u001b[39;00m(\u001b[38;5;124m\"\u001b[39m\u001b[38;5;124mTimeout connecting to server\u001b[39m\u001b[38;5;124m\"\u001b[39m)\n\u001b[1;32m    281\u001b[0m \u001b[38;5;28;01mexcept\u001b[39;00m \u001b[38;5;167;01mOSError\u001b[39;00m \u001b[38;5;28;01mas\u001b[39;00m e:\n\u001b[0;32m--> 282\u001b[0m     \u001b[38;5;28;01mraise\u001b[39;00m \u001b[38;5;167;01mConnectionError\u001b[39;00m(\u001b[38;5;28mself\u001b[39m\u001b[38;5;241m.\u001b[39m_error_message(e))\n\u001b[1;32m    284\u001b[0m \u001b[38;5;28mself\u001b[39m\u001b[38;5;241m.\u001b[39m_sock \u001b[38;5;241m=\u001b[39m sock\n\u001b[1;32m    285\u001b[0m \u001b[38;5;28;01mtry\u001b[39;00m:\n",
      "\u001b[0;31mConnectionError\u001b[0m: Error 111 connecting to localhost:6379. Connection refused."
     ]
    }
   ],
   "source": [
    "keys = ['name', 'name1', 'name2','age', 'age1', 'age2']\n",
    "values = redis_client.mget(keys)\n",
    "\n",
    "for key, value in zip(keys, values):\n",
    "    print(f\"{key}: {value.decode('utf-8')}\")"
   ]
  },
  {
   "cell_type": "code",
   "execution_count": 8,
   "metadata": {},
   "outputs": [
    {
     "ename": "ConnectionError",
     "evalue": "Error 111 connecting to localhost:6379. Connection refused.",
     "output_type": "error",
     "traceback": [
      "\u001b[0;31m---------------------------------------------------------------------------\u001b[0m",
      "\u001b[0;31mConnectionRefusedError\u001b[0m                    Traceback (most recent call last)",
      "File \u001b[0;32m/usr/local/lib/python3.10/dist-packages/redis/connection.py:276\u001b[0m, in \u001b[0;36mAbstractConnection.connect\u001b[0;34m(self)\u001b[0m\n\u001b[1;32m    275\u001b[0m \u001b[38;5;28;01mtry\u001b[39;00m:\n\u001b[0;32m--> 276\u001b[0m     sock \u001b[38;5;241m=\u001b[39m \u001b[38;5;28;43mself\u001b[39;49m\u001b[38;5;241;43m.\u001b[39;49m\u001b[43mretry\u001b[49m\u001b[38;5;241;43m.\u001b[39;49m\u001b[43mcall_with_retry\u001b[49m\u001b[43m(\u001b[49m\n\u001b[1;32m    277\u001b[0m \u001b[43m        \u001b[49m\u001b[38;5;28;43;01mlambda\u001b[39;49;00m\u001b[43m:\u001b[49m\u001b[43m \u001b[49m\u001b[38;5;28;43mself\u001b[39;49m\u001b[38;5;241;43m.\u001b[39;49m\u001b[43m_connect\u001b[49m\u001b[43m(\u001b[49m\u001b[43m)\u001b[49m\u001b[43m,\u001b[49m\u001b[43m \u001b[49m\u001b[38;5;28;43;01mlambda\u001b[39;49;00m\u001b[43m \u001b[49m\u001b[43merror\u001b[49m\u001b[43m:\u001b[49m\u001b[43m \u001b[49m\u001b[38;5;28;43mself\u001b[39;49m\u001b[38;5;241;43m.\u001b[39;49m\u001b[43mdisconnect\u001b[49m\u001b[43m(\u001b[49m\u001b[43merror\u001b[49m\u001b[43m)\u001b[49m\n\u001b[1;32m    278\u001b[0m \u001b[43m    \u001b[49m\u001b[43m)\u001b[49m\n\u001b[1;32m    279\u001b[0m \u001b[38;5;28;01mexcept\u001b[39;00m socket\u001b[38;5;241m.\u001b[39mtimeout:\n",
      "File \u001b[0;32m/usr/local/lib/python3.10/dist-packages/redis/retry.py:46\u001b[0m, in \u001b[0;36mRetry.call_with_retry\u001b[0;34m(self, do, fail)\u001b[0m\n\u001b[1;32m     45\u001b[0m \u001b[38;5;28;01mtry\u001b[39;00m:\n\u001b[0;32m---> 46\u001b[0m     \u001b[38;5;28;01mreturn\u001b[39;00m \u001b[43mdo\u001b[49m\u001b[43m(\u001b[49m\u001b[43m)\u001b[49m\n\u001b[1;32m     47\u001b[0m \u001b[38;5;28;01mexcept\u001b[39;00m \u001b[38;5;28mself\u001b[39m\u001b[38;5;241m.\u001b[39m_supported_errors \u001b[38;5;28;01mas\u001b[39;00m error:\n",
      "File \u001b[0;32m/usr/local/lib/python3.10/dist-packages/redis/connection.py:277\u001b[0m, in \u001b[0;36mAbstractConnection.connect.<locals>.<lambda>\u001b[0;34m()\u001b[0m\n\u001b[1;32m    275\u001b[0m \u001b[38;5;28;01mtry\u001b[39;00m:\n\u001b[1;32m    276\u001b[0m     sock \u001b[38;5;241m=\u001b[39m \u001b[38;5;28mself\u001b[39m\u001b[38;5;241m.\u001b[39mretry\u001b[38;5;241m.\u001b[39mcall_with_retry(\n\u001b[0;32m--> 277\u001b[0m         \u001b[38;5;28;01mlambda\u001b[39;00m: \u001b[38;5;28;43mself\u001b[39;49m\u001b[38;5;241;43m.\u001b[39;49m\u001b[43m_connect\u001b[49m\u001b[43m(\u001b[49m\u001b[43m)\u001b[49m, \u001b[38;5;28;01mlambda\u001b[39;00m error: \u001b[38;5;28mself\u001b[39m\u001b[38;5;241m.\u001b[39mdisconnect(error)\n\u001b[1;32m    278\u001b[0m     )\n\u001b[1;32m    279\u001b[0m \u001b[38;5;28;01mexcept\u001b[39;00m socket\u001b[38;5;241m.\u001b[39mtimeout:\n",
      "File \u001b[0;32m/usr/local/lib/python3.10/dist-packages/redis/connection.py:639\u001b[0m, in \u001b[0;36mConnection._connect\u001b[0;34m(self)\u001b[0m\n\u001b[1;32m    638\u001b[0m \u001b[38;5;28;01mif\u001b[39;00m err \u001b[38;5;129;01mis\u001b[39;00m \u001b[38;5;129;01mnot\u001b[39;00m \u001b[38;5;28;01mNone\u001b[39;00m:\n\u001b[0;32m--> 639\u001b[0m     \u001b[38;5;28;01mraise\u001b[39;00m err\n\u001b[1;32m    640\u001b[0m \u001b[38;5;28;01mraise\u001b[39;00m \u001b[38;5;167;01mOSError\u001b[39;00m(\u001b[38;5;124m\"\u001b[39m\u001b[38;5;124msocket.getaddrinfo returned an empty list\u001b[39m\u001b[38;5;124m\"\u001b[39m)\n",
      "File \u001b[0;32m/usr/local/lib/python3.10/dist-packages/redis/connection.py:627\u001b[0m, in \u001b[0;36mConnection._connect\u001b[0;34m(self)\u001b[0m\n\u001b[1;32m    626\u001b[0m \u001b[38;5;66;03m# connect\u001b[39;00m\n\u001b[0;32m--> 627\u001b[0m \u001b[43msock\u001b[49m\u001b[38;5;241;43m.\u001b[39;49m\u001b[43mconnect\u001b[49m\u001b[43m(\u001b[49m\u001b[43msocket_address\u001b[49m\u001b[43m)\u001b[49m\n\u001b[1;32m    629\u001b[0m \u001b[38;5;66;03m# set the socket_timeout now that we're connected\u001b[39;00m\n",
      "\u001b[0;31mConnectionRefusedError\u001b[0m: [Errno 111] Connection refused",
      "\nDuring handling of the above exception, another exception occurred:\n",
      "\u001b[0;31mConnectionError\u001b[0m                           Traceback (most recent call last)",
      "Cell \u001b[0;32mIn[8], line 2\u001b[0m\n\u001b[1;32m      1\u001b[0m \u001b[38;5;66;03m#delete all\u001b[39;00m\n\u001b[0;32m----> 2\u001b[0m \u001b[43mredis_client\u001b[49m\u001b[38;5;241;43m.\u001b[39;49m\u001b[43mflushall\u001b[49m\u001b[43m(\u001b[49m\u001b[43m)\u001b[49m\n\u001b[1;32m      4\u001b[0m \u001b[38;5;28mprint\u001b[39m(\u001b[38;5;124m\"\u001b[39m\u001b[38;5;124mAll data deleted from the Redis database.\u001b[39m\u001b[38;5;124m\"\u001b[39m)\n",
      "File \u001b[0;32m/usr/local/lib/python3.10/dist-packages/redis/commands/core.py:932\u001b[0m, in \u001b[0;36mManagementCommands.flushall\u001b[0;34m(self, asynchronous, **kwargs)\u001b[0m\n\u001b[1;32m    930\u001b[0m \u001b[38;5;28;01mif\u001b[39;00m asynchronous:\n\u001b[1;32m    931\u001b[0m     args\u001b[38;5;241m.\u001b[39mappend(\u001b[38;5;124mb\u001b[39m\u001b[38;5;124m\"\u001b[39m\u001b[38;5;124mASYNC\u001b[39m\u001b[38;5;124m\"\u001b[39m)\n\u001b[0;32m--> 932\u001b[0m \u001b[38;5;28;01mreturn\u001b[39;00m \u001b[38;5;28;43mself\u001b[39;49m\u001b[38;5;241;43m.\u001b[39;49m\u001b[43mexecute_command\u001b[49m\u001b[43m(\u001b[49m\u001b[38;5;124;43m\"\u001b[39;49m\u001b[38;5;124;43mFLUSHALL\u001b[39;49m\u001b[38;5;124;43m\"\u001b[39;49m\u001b[43m,\u001b[49m\u001b[43m \u001b[49m\u001b[38;5;241;43m*\u001b[39;49m\u001b[43margs\u001b[49m\u001b[43m,\u001b[49m\u001b[43m \u001b[49m\u001b[38;5;241;43m*\u001b[39;49m\u001b[38;5;241;43m*\u001b[39;49m\u001b[43mkwargs\u001b[49m\u001b[43m)\u001b[49m\n",
      "File \u001b[0;32m/usr/local/lib/python3.10/dist-packages/redis/client.py:542\u001b[0m, in \u001b[0;36mRedis.execute_command\u001b[0;34m(self, *args, **options)\u001b[0m\n\u001b[1;32m    540\u001b[0m pool \u001b[38;5;241m=\u001b[39m \u001b[38;5;28mself\u001b[39m\u001b[38;5;241m.\u001b[39mconnection_pool\n\u001b[1;32m    541\u001b[0m command_name \u001b[38;5;241m=\u001b[39m args[\u001b[38;5;241m0\u001b[39m]\n\u001b[0;32m--> 542\u001b[0m conn \u001b[38;5;241m=\u001b[39m \u001b[38;5;28mself\u001b[39m\u001b[38;5;241m.\u001b[39mconnection \u001b[38;5;129;01mor\u001b[39;00m \u001b[43mpool\u001b[49m\u001b[38;5;241;43m.\u001b[39;49m\u001b[43mget_connection\u001b[49m\u001b[43m(\u001b[49m\u001b[43mcommand_name\u001b[49m\u001b[43m,\u001b[49m\u001b[43m \u001b[49m\u001b[38;5;241;43m*\u001b[39;49m\u001b[38;5;241;43m*\u001b[39;49m\u001b[43moptions\u001b[49m\u001b[43m)\u001b[49m\n\u001b[1;32m    544\u001b[0m \u001b[38;5;28;01mtry\u001b[39;00m:\n\u001b[1;32m    545\u001b[0m     \u001b[38;5;28;01mreturn\u001b[39;00m conn\u001b[38;5;241m.\u001b[39mretry\u001b[38;5;241m.\u001b[39mcall_with_retry(\n\u001b[1;32m    546\u001b[0m         \u001b[38;5;28;01mlambda\u001b[39;00m: \u001b[38;5;28mself\u001b[39m\u001b[38;5;241m.\u001b[39m_send_command_parse_response(\n\u001b[1;32m    547\u001b[0m             conn, command_name, \u001b[38;5;241m*\u001b[39margs, \u001b[38;5;241m*\u001b[39m\u001b[38;5;241m*\u001b[39moptions\n\u001b[1;32m    548\u001b[0m         ),\n\u001b[1;32m    549\u001b[0m         \u001b[38;5;28;01mlambda\u001b[39;00m error: \u001b[38;5;28mself\u001b[39m\u001b[38;5;241m.\u001b[39m_disconnect_raise(conn, error),\n\u001b[1;32m    550\u001b[0m     )\n",
      "File \u001b[0;32m/usr/local/lib/python3.10/dist-packages/redis/connection.py:1109\u001b[0m, in \u001b[0;36mConnectionPool.get_connection\u001b[0;34m(self, command_name, *keys, **options)\u001b[0m\n\u001b[1;32m   1105\u001b[0m     \u001b[38;5;28mself\u001b[39m\u001b[38;5;241m.\u001b[39m_in_use_connections\u001b[38;5;241m.\u001b[39madd(connection)\n\u001b[1;32m   1107\u001b[0m \u001b[38;5;28;01mtry\u001b[39;00m:\n\u001b[1;32m   1108\u001b[0m     \u001b[38;5;66;03m# ensure this connection is connected to Redis\u001b[39;00m\n\u001b[0;32m-> 1109\u001b[0m     \u001b[43mconnection\u001b[49m\u001b[38;5;241;43m.\u001b[39;49m\u001b[43mconnect\u001b[49m\u001b[43m(\u001b[49m\u001b[43m)\u001b[49m\n\u001b[1;32m   1110\u001b[0m     \u001b[38;5;66;03m# connections that the pool provides should be ready to send\u001b[39;00m\n\u001b[1;32m   1111\u001b[0m     \u001b[38;5;66;03m# a command. if not, the connection was either returned to the\u001b[39;00m\n\u001b[1;32m   1112\u001b[0m     \u001b[38;5;66;03m# pool before all data has been read or the socket has been\u001b[39;00m\n\u001b[1;32m   1113\u001b[0m     \u001b[38;5;66;03m# closed. either way, reconnect and verify everything is good.\u001b[39;00m\n\u001b[1;32m   1114\u001b[0m     \u001b[38;5;28;01mtry\u001b[39;00m:\n",
      "File \u001b[0;32m/usr/local/lib/python3.10/dist-packages/redis/connection.py:282\u001b[0m, in \u001b[0;36mAbstractConnection.connect\u001b[0;34m(self)\u001b[0m\n\u001b[1;32m    280\u001b[0m     \u001b[38;5;28;01mraise\u001b[39;00m \u001b[38;5;167;01mTimeoutError\u001b[39;00m(\u001b[38;5;124m\"\u001b[39m\u001b[38;5;124mTimeout connecting to server\u001b[39m\u001b[38;5;124m\"\u001b[39m)\n\u001b[1;32m    281\u001b[0m \u001b[38;5;28;01mexcept\u001b[39;00m \u001b[38;5;167;01mOSError\u001b[39;00m \u001b[38;5;28;01mas\u001b[39;00m e:\n\u001b[0;32m--> 282\u001b[0m     \u001b[38;5;28;01mraise\u001b[39;00m \u001b[38;5;167;01mConnectionError\u001b[39;00m(\u001b[38;5;28mself\u001b[39m\u001b[38;5;241m.\u001b[39m_error_message(e))\n\u001b[1;32m    284\u001b[0m \u001b[38;5;28mself\u001b[39m\u001b[38;5;241m.\u001b[39m_sock \u001b[38;5;241m=\u001b[39m sock\n\u001b[1;32m    285\u001b[0m \u001b[38;5;28;01mtry\u001b[39;00m:\n",
      "\u001b[0;31mConnectionError\u001b[0m: Error 111 connecting to localhost:6379. Connection refused."
     ]
    }
   ],
   "source": [
    "#delete all\n",
    "redis_client.flushall()\n",
    "\n",
    "print(\"All data deleted from the Redis database.\")"
   ]
  }
 ],
 "metadata": {
  "kernelspec": {
   "display_name": "Python 3",
   "language": "python",
   "name": "python3"
  },
  "language_info": {
   "codemirror_mode": {
    "name": "ipython",
    "version": 3
   },
   "file_extension": ".py",
   "mimetype": "text/x-python",
   "name": "python",
   "nbconvert_exporter": "python",
   "pygments_lexer": "ipython3",
   "version": "3.10.12"
  }
 },
 "nbformat": 4,
 "nbformat_minor": 2
}
